Workbook

Sheet Leave by Employee
A1: Leave by Employee
A2: (January 2026 - February 2026)
A4: Employee | B4: Team | C4: Country | D4: Group | E4: Annual Leave Entitlement | F4: Annual Leave Booked | G4: Annual Leave Remaining | H4: WFH Entitlement | I4: WFH Booked | J4: WFH Variance | K4: Medical/Sick Taken | L4: External Assignments Taken | M4: Other Taken | N4: Total Variation
A5: Albano Limas | B5: Engineering | C5: UK | D5: EG | E5: 31 | F5: 4 | G5: 27 | H5: 9 | I5: 0 | J5: 9 | K5: 0 | L5: 0 | M5: 0
A6: Alex McGregor | B6: Investment | C6: UK | D6: EG | E6: 18.5 | F6: 13 | G6: 5.5 | H6: 9 | I6: 4 | J6: 5 | K6: 0 | L6: 0 | M6: 0 | N6: =VLOOKUP(A6,Sheet1!A:B,2,FALSE) -> 2.29
A7: Alex William McGregor | B7: Investment | C7: UK | D7: EG | E7: 18.5 | F7: 0 | G7: 18.5 | H7: 9 | I7: 0 | J7: 9 | K7: 0 | L7: 0 | M7: 0
A8: Amine El Fassi | B8: Engineering | C8: UK | D8: EG | E8: 20 | F8: 0 | G8: 20 | H8: 9 | I8: 0 | J8: 9 | K8: 0 | L8: 0 | M8: 0 | N8: =VLOOKUP(A8,Sheet1!A:B,2,FALSE) -> 6.9
A9: Andreea Cartianu | B9: UG Business Support | C9: UK | D9: UG | E9: 20 | F9: 5 | G9: 15 | H9: 9 | I9: 0 | J9: 9 | K9: 0 | L9: 0 | M9: 0 | N9: =VLOOKUP(A9,Sheet1!A:B,2,FALSE) -> -3.54
A10: Ariana Mashad | B10: Agri | C10: UK | D10: AG | E10: 20 | F10: 0 | G10: 20 | H10: 9 | I10: 0 | J10: 9 | K10: 0 | L10: 0 | M10: 0 | N10: =VLOOKUP(A10,Sheet1!A:B,2,FALSE) -> 17.11
A11: Barış Akyüz | B11: Engineering | C11: UK | D11: EG | E11: 27 | F11: 10 | G11: 17 | H11: 9 | I11: 3 | J11: 6 | K11: 2 | L11: 0 | M11: 0 | N11: =VLOOKUP(A11,Sheet1!A:B,2,FALSE) -> 4.98
A12: Benjamin Hahn | B12: DE BDM | C12: Germany | D12: EG | E12: 32.5 | F12: 19.5 | G12: 13 | H12: 9 | I12: 4 | J12: 5 | K12: 2 | L12: 2 | M12: 0
A13: Charles Jones | B13: UK BDM | C13: UK | D13: EG | E13: 20.5 | F13: 4 | G13: 16.5 | H13: 9 | I13: 3 | J13: 6 | K13: 0 | L13: 0 | M13: 0 | N13: =VLOOKUP(A13,Sheet1!A:B,2,FALSE) -> 3.32
A14: Charlotta Personn | B14: DE BDM | C14: Germany | D14: EG | E14: 28 | F14: 18 | G14: 10 | H14: 9 | I14: 8 | J14: 1 | K14: 0 | L14: 0 | M14: 0
A15: Daniel Imran | B15: Group Finance | C15: UK | D15: UG | E15: 28 | F15: 2 | G15: 26 | H15: 9 | I15: 0 | J15: 9 | K15: 0 | L15: 0 | M15: 0 | N15: =VLOOKUP(A15,Sheet1!A:B,2,FALSE) -> -1.48
A16: Dominic Richardson | B16: UK BDM | C16: UK | D16: EG | E16: 27.5 | F16: 22 | G16: 5.5 | H16: 9 | I16: 17 | J16: -8 | K16: 1 | L16: 0 | M16: 0 | N16: =VLOOKUP(A16,Sheet1!A:B,2,FALSE) -> 3.84
A17: Dominick Mahon | B17: Investment | C17: UK | D17: EG | E17: 22.5 | F17: 5 | G17: 17.5 | H17: 9 | I17: 2 | J17: 7 | K17: 0 | L17: 0 | M17: 0 | N17: =VLOOKUP(A17,Sheet1!A:B,2,FALSE) -> 16.69
A18: Ecaterina Turcanu | B18: Operations | C18: UK | D18: EG | E18: 30.5 | F18: 13 | G18: 17.5 | H18: 9 | I18: 0 | J18: 9 | K18: 0 | L18: 4 | M18: 0 | N18: =VLOOKUP(A18,Sheet1!A:B,2,FALSE) -> 12.9
A19: Elena Sarieva | B19: UK BDM | C19: UK | D19: EG | E19: 25 | F19: 5 | G19: 20 | H19: 9 | I19: 6.5 | J19: 2.5 | K19: 0 | L19: 0 | M19: 0 | N19: =VLOOKUP(A19,Sheet1!A:B,2,FALSE) -> 7.72
A20: Elias Zimmerman | B20: DE BDM | C20: Germany | D20: EG | E20: 14.5 | F20: 0 | G20: 14.5 | H20: 9 | I20: 0 | J20: 9 | K20: 0 | L20: 0 | M20: 0
A21: Elizabeth Kinnear-Mellor | B21: UK BDM | C21: UK | D21: EG | E21: 16 | F21: 6 | G21: 10 | H21: 9 | I21: 0 | J21: 9 | K21: 0 | L21: 0 | M21: 0
A22: Eugene Sun | B22: Engineering | C22: UK | D22: EG | E22: 22.5 | F22: 4 | G22: 18.5 | H22: 9 | I22: 0 | J22: 9 | K22: 0 | L22: 0 | M22: 0 | N22: =VLOOKUP(A22,Sheet1!A:B,2,FALSE) -> 9.78
A23: Fabian Tippelt | B23: DE BDM | C23: Germany | D23: EG | E23: 27 | F23: 2 | G23: 25 | H23: 9 | I23: 0 | J23: 9 | K23: 0 | L23: 0 | M23: 0
A24: Florina Stamate | B24: Finance | C24: UK | D24: UG | E24: 24 | F24: 14.5 | G24: 9.5 | H24: 9 | I24: 5 | J24: 4 | K24: 0 | L24: 0 | M24: 0 | N24: =VLOOKUP(A24,Sheet1!A:B,2,FALSE) -> 5.37
A25: George Hanna | B25: Group Legal | C25: UK | D25: UG | E25: 23 | F25: 6 | G25: 17 | H25: 9 | I25: 0 | J25: 9 | K25: 0 | L25: 0 | M25: 0 | N25: =VLOOKUP(A25,Sheet1!A:B,2,FALSE) -> 3.36
A26: Hadi Zohreie | B26: Agri | C26: UK | D26: AG | E26: 20 | F26: 0 | G26: 20 | H26: 9 | I26: 0 | J26: 9 | K26: 0 | L26: 0 | M26: 0 | N26: =VLOOKUP(A26,Sheet1!A:B,2,FALSE) -> -6.19
A27: Hamza Aissani | B27: Agri | C27: UK | D27: AG | E27: 20 | F27: 10 | G27: 10 | H27: 9 | I27: 1 | J27: 8 | K27: 0 | L27: 0 | M27: 0 | N27: =VLOOKUP(A27,Sheet1!A:B,2,FALSE) -> 2.57
A28: Harsh Malhotra | B28: Operations | C28: UK | D28: EG | E28: 19.5 | F28: 0 | G28: 19.5 | H28: 9 | I28: 0 | J28: 9 | K28: 0 | L28: 0 | M28: 0 | N28: =VLOOKUP(A28,Sheet1!A:B,2,FALSE) -> 7.18
A29: Hyfa Azeez | B29: Group Legal | C29: UK | D29: UG | E29: 23.5 | F29: 5 | G29: 18.5 | H29: 9 | I29: 0 | J29: 9 | K29: 0 | L29: 0 | M29: 0 | N29: =VLOOKUP(A29,Sheet1!A:B,2,FALSE) -> 15.39
A30: Jae Seung Lee | B30: Property | C30: UK | D30: UG | E30: 32 | F30: 9 | G30: 23 | H30: 9 | I30: 0 | J30: 9 | K30: 0 | L30: 0 | M30: 0
A31: James Gates | B31: Investment | C31: UK | D31: EG | E31: 22 | F31: 0 | G31: 22 | H31: 9 | I31: 0 | J31: 9 | K31: 0 | L31: 0 | M31: 0
A32: James Shelton | B32: Agri | C32: UK | D32: AG | E32: 25.5 | F32: 6 | G32: 19.5 | H32: 9 | I32: 0 | J32: 9 | K32: 0 | L32: 0 | M32: 0 | N32: =VLOOKUP(A32,Sheet1!A:B,2,FALSE) -> 38.14
A33: Jamie Rixton | B33: Agri | C33: UK | D33: AG | E33: 20 | F33: 0 | G33: 20 | H33: 9 | I33: 0 | J33: 9 | K33: 0 | L33: 0 | M33: 0
A34: Jannes Thomesen | B34: DE BDM | C34: Germany | D34: EG | E34: 34.5 | F34: 0 | G34: 34.5 | H34: 9 | I34: 0 | J34: 9 | K34: 0 | L34: 0 | M34: 0
A35: John Hetherton | B35: UK BDM | C35: UK | D35: EG | E35: 24.5 | F35: 2 | G35: 22.5 | H35: 9 | I35: 0 | J35: 9 | K35: 0 | L35: 0 | M35: 0 | N35: =VLOOKUP(A35,Sheet1!A:B,2,FALSE) -> 6.71
A36: Joshua Mathias | B36: Investment | C36: UK | D36: EG | E36: 26 | F36: 6.5 | G36: 19.5 | H36: 9 | I36: 0 | J36: 9 | K36: 1 | L36: 0 | M36: 0 | N36: =VLOOKUP(A36,Sheet1!A:B,2,FALSE) -> 11.54
A37: Kelly Lima | B37: UG Business Support | C37: UK | D37: UG | E37: 29.5 | F37: 8.5 | G37: 21 | H37: 9 | I37: 0 | J37: 9 | K37: 0 | L37: 0 | M37: 0 | N37: =VLOOKUP(A37,Sheet1!A:B,2,FALSE) -> -0.57
A38: Kiabod Mashad | B38: Property | C38: UK | D38: UG | E38: 20 | F38: 0 | G38: 20 | H38: 9 | I38: 0 | J38: 9 | K38: 0 | L38: 0 | M38: 0 | N38: =VLOOKUP(A38,Sheet1!A:B,2,FALSE) -> -4.69
A39: Lisa Ter-Berg | B39: Operations | C39: UK | D39: EG | E39: 20 | F39: 5 | G39: 15 | H39: 9 | I39: 0 | J39: 9 | K39: 1 | L39: 0 | M39: 0 | N39: =VLOOKUP(A39,Sheet1!A:B,2,FALSE) -> 6.22
A40: Lizzie Atkin | B40: UK BDM | C40: UK | D40: EG | E40: 24 | F40: 5 | G40: 19 | H40: 9 | I40: 5.5 | J40: 3.5 | K40: 0 | L40: 0 | M40: 0 | N40: =VLOOKUP(A40,Sheet1!A:B,2,FALSE) -> 5.69
A41: Lydia Kerbel | B41: DE BDM | C41: Germany | D41: EG | E41: 25 | F41: 5 | G41: 20 | H41: 9 | I41: 0 | J41: 9 | K41: 0 | L41: 0 | M41: 0
...

Sheet Leave by Department
A1: Leave by Department
A2: (January 2026 - February 2026)
A4: Department | B4: Headcount | C4: Annual Leave Entitlement | D4: Annual Leave Booked | E4: Annual Leave Remaining | F4: WFH Entitlement | G4: WFH Booked | H4: WFH Variance | I4: Medical/Sick Taken | J4: External Assignments Taken | K4: Other Taken
A5: Agri | B5: 9 | C5: 187.5 | D5: 21 | E5: 166.5 | F5: 81 | G5: 1 | H5: 80 | I5: 2 | J5: 0 | K5: 0
A6: DE BDM | B6: 13 | C6: 384 | D6: 115 | E6: 269 | F6: 117 | G6: 30.5 | H6: 86.5 | I6: 29 | J6: 3 | K6: 0
A7: Engineering | B7: 6 | C7: 150.5 | D7: 23 | E7: 127.5 | F7: 54 | G7: 3 | H7: 51 | I7: 2 | J7: 0 | K7: 0
A8: Finance | B8: 6 | C8: 143.5 | D8: 39.5 | E8: 104 | F8: 54 | G8: 49.5 | H8: 4.5 | I8: 4.5 | J8: 3 | K8: 0
A9: Group Finance | B9: 4 | C9: 98.5 | D9: 2 | E9: 96.5 | F9: 36 | G9: 0 | H9: 36 | I9: 0 | J9: 3 | K9: 0
A10: Group Legal | B10: 4 | C10: 91 | D10: 11 | E10: 80 | F10: 36 | G10: 0 | H10: 36 | I10: 0 | J10: 0 | K10: 0
A11: HR | B11: 2 | C11: 41 | D11: 8 | E11: 33 | F11: 18 | G11: 5 | H11: 13 | I11: 0 | J11: 3 | K11: 0
A12: Investment | B12: 7 | C12: 147.5 | D12: 24.5 | E12: 123 | F12: 63 | G12: 6 | H12: 57 | I12: 1 | J12: 0 | K12: 0
A13: Management | B13: 2 | C13: 42 | D13: 2 | E13: 40 | F13: 18 | G13: 0 | H13: 18 | I13: 0 | J13: 0 | K13: 0
A14: Operations | B14: 4 | C14: 94 | D14: 27.5 | E14: 66.5 | F14: 36 | G14: 3 | H14: 33 | I14: 1 | J14: 4 | K14: 0
A15: Property | B15: 3 | C15: 72.5 | D15: 9 | E15: 63.5 | F15: 27 | G15: 0 | H15: 27 | I15: 0 | J15: 0 | K15: 0
A16: UG Business Support | B16: 2 | C16: 49.5 | D16: 13.5 | E16: 36 | F16: 18 | G16: 0 | H16: 18 | I16: 0 | J16: 0 | K16: 0
A17: UK BDM | B17: 10 | C17: 224 | D17: 64 | E17: 160 | F17: 90 | G17: 39.5 | H17: 50.5 | I17: 3 | J17: 5 | K17: 0

Sheet Leave by Country
A1: Leave by Country
A2: (January 2026 - February 2026)
A4: Country | B4: Headcount | C4: Annual Leave Entitlement | D4: Annual Leave Booked | E4: Annual Leave Remaining | F4: WFH Entitlement | G4: WFH Booked | H4: WFH Variance | I4: Medical/Sick Taken | J4: External Assignments Taken | K4: Other Taken
A5: Germany | B5: 13 | C5: 384 | D5: 115 | E5: 269 | F5: 117 | G5: 30.5 | H5: 86.5 | I5: 29 | J5: 3 | K5: 0
A6: UK | B6: 67 | C6: 1341.5 | D6: 245 | E6: 1096.5 | F6: 107 | G6: 531 | H6: 424 | I6: 13.5 | J6: 18 | K6: 0

Sheet Leave by Group
A1: Leave by Group
A2: (January 2026 - February 2026)
A4: Group | B4: Headcount | C4: Annual Leave Entitlement | D4: Annual Leave Booked | E4: Annual Leave Remaining | F4: WFH Entitlement | G4: WFH Booked | H4: WFH Variance | I4: Medical/Sick Taken | J4: External Assignments Taken | K4: Other Taken
A5: AG | B5: 9 | C5: 187.5 | D5: 21 | E5: 166.5 | F5: 81 | G5: 1 | H5: 80 | I5: 2 | J5: 0 | K5: 0
A6: EG | B6: 42 | C6: 1041 | D6: 262 | E6: 779 | F6: 378 | G6: 87 | H6: 291 | I6: 36 | J6: 15 | K6: 0
A7: UG | B7: 21 | C7: 497 | D7: 77 | E7: 420 | F7: 189 | G7: 49.5 | H7: 139.5 | I7: 4.5 | J7: 6 | K7: 0

Sheet Time by Employee
A1: Time by Employee
A2: (27th Jan 2026 - 18th Feb 2026)
B4: Alex McGregor | G4: Amine El Fassi | L4: Andreea Cartianu | Q4: Ariana Mashad | V4: Barış Akyüz | AA4: Charles Jones | AF4: Daniel Imran | AK4: Dominic Richardson | AP4: Dominick Mahon | AU4: Ecaterina Turcanu | AZ4: Elena Sarieva | BE4: Eugene Sun | BJ4: Florina Stamate | BO4: George Hanna | BT4: Hadi Zohreie | BY4: Hamza Aissani | CD4: Harsh Malhotra | CI4: Hyfa Azeez | CN4: James Shelton | CS4: John Hetherton | CX4: Joshua Mathias | DC4: Kelly Lima | DH4: Kiabod Mashad | DM4: Lisa Ter-Berg | DR4: Lizzie Atkin | DW4: Maria Titova | EB4: Mark Wheeler | EG4: Max Kinghorn | EL4: Nidhi Daga | EQ4: Philip Woolfson | EV4: Rupal Sutar | FA4: Ryan Holland | FF4: Selin Bakare | FK4: Senthurgan Kulendran | FP4: Shafraz Chatur | FU4: Stefanie Lenehan | FZ4: Teddy Powell | GE4: Tom Richold | GJ4: Umair Shaikh | GO4: Valentina Testa | GT4: Yi Jiang
B5: In | C5: Out | D5: Break | E5: Var | G5: In | H5: Out | I5: Break | J5: Var | L5: In | M5: Out | N5: Break | O5: Var | Q5: In | R5: Out | S5: Break | T5: Var | V5: In | W5: Out | X5: Break | Y5: Var | AA5: In | AB5: Out | AC5: Break | AD5: Var | AF5: In | AG5: Out | AH5: Break | AI5: Var | AK5: In | AL5: Out | AM5: Break | AN5: Var | AP5: In | AQ5: Out | AR5: Break | AS5: Var | AU5: In | AV5: Out | AW5: Break | AX5: Var | AZ5: In | BA5: Out | BB5: Break | BC5: Var | BE5: In | BF5: Out | BG5: Break | BH5: Var | BJ5: In | BK5: Out | BL5: Break | BM5: Var | BO5: In | BP5: Out | BQ5: Break | BR5: Var | BT5: In | BU5: Out | BV5: Break | BW5: Var | BY5: In | BZ5: Out | CA5: Break | CB5: Var | CD5: In | CE5: Out | CF5: Break | CG5: Var | CI5: In | CJ5: Out | CK5: Break | CL5: Var | CN5: In | CO5: Out | CP5: Break | CQ5: Var | CS5: In | CT5: Out | CU5: Break | CV5: Var | CX5: In | CY5: Out | CZ5: Break | DA5: Var | DC5: In | DD5: Out | DE5: Break | DF5: Var | DH5: In | DI5: Out | DJ5: Break | DK5: Var | DM5: In | DN5: Out | DO5: Break | DP5: Var | DR5: In | DS5: Out | DT5: Break | DU5: Var | DW5: In | DX5: Out | DY5: Break | DZ5: Var | EB5: In | EC5: Out | ED5: Break | EE5: Var | EG5: In | EH5: Out | EI5: Break | EJ5: Var | EL5: In | EM5: Out | EN5: Break | EO5: Var | EQ5: In | ER5: Out | ES5: Break | ET5: Var | EV5: In | EW5: Out | EX5: Break | EY5: Var | FA5: In | FB5: Out | FC5: Break | FD5: Var | FF5: In | FG5: Out | FH5: Break | FI5: Var | FK5: In | FL5: Out | FM5: Break | FN5: Var | FP5: In | FQ5: Out | FR5: Break | FS5: Var | FU5: In | FV5: Out | FW5: Break | FX5: Var | FZ5: In | GA5: Out | GB5: Break | GC5: Var | GE5: In | GF5: Out | GG5: Break | GH5: Var | GJ5: In | GK5: Out | GL5: Break | GM5: Var | GO5: In | GP5: Out | GQ5: Break | GR5: Var | GT5: In | GU5: Out | GV5: Break | GW5: Var
A6: 2026-01-27 | B6: 09:00 | C6: 17:00 | D6: 00:30 | E6: 0 | G6: 09:03 | H6: 17:30 | I6: 00:32 | J6: 0.41 | L6: 13:44 | M6: 17:42 | N6: 00:37 | O6: -4.16 | Q6: 08:51 | R6: 19:37 | S6: 00:31 | T6: 2.75 | V6: 09:08 | W6: 17:30 | X6: 00:36 | Y6: 0.26 | AA6: 08:32 | AB6: 17:30 | AC6: 00:30 | AD6: 0.96 | AF6: 09:55 | AG6: 17:44 | AH6: 00:42 | AI6: -0.39 | AK6: 08:54 | AL6: 17:30 | AM6: 00:38 | AN6: 0.45 | AP6: 09:00 | AQ6: 17:00 | AR6: 00:30 | AS6: 0 | AU6: 09:29 | AV6: 17:34 | AW6: 00:36 | AX6: -0.02 | AZ6: 08:45 | BA6: 17:30 | BB6: 00:30 | BC6: 0.74 | BE6: 08:53 | BF6: 17:49 | BG6: 00:45 | BH6: 0.67 | BJ6: 09:04 | BK6: 17:36 | BL6: 00:41 | BM6: 0.36 | BO6: 09:14 | BP6: 17:30 | BQ6: 00:34 | BR6: 0.2 | BT6: 09:00 | BU6: 17:00 | BV6: 00:30 | BW6: 0 | BY6: 09:04 | BZ6: 17:16 | CA6: 00:34 | CB6: 0.13 | CD6: 08:50 | CE6: 17:35 | CF6: 00:33 | CG6: 0.7 | CI6: 09:14 | CJ6: 17:30 | CK6: 00:37 | CL6: 0.14 | CN6: 08:51 | CO6: 19:36 | CP6: 00:40 | CQ6: 2.6 | CS6: 10:10 | CT6: 19:32 | CU6: 00:43 | CV6: 1.16 | CX6: 09:13 | CY6: 17:30 | CZ6: 00:39 | DA6: 0.12 | DC6: 09:00 | DD6: 17:00 | DE6: 00:30 | DF6: 0 | DH6: 09:00 | DI6: 17:00 | DJ6: 00:30 | DK6: 0 | DM6: 09:00 | DN6: 17:30 | DO6: 00:37 | DP6: 0.37 | DR6: 08:50 | DS6: 17:30 | DT6: 00:43 | DU6: 0.44 | DW6: 09:29 | DX6: 17:25 | DY6: 00:36 | DZ6: -0.16 | EB6: 09:00 | EC6: 17:00 | ED6: 00:30 | EE6: 0 | EG6: 09:00 | EH6: 17:00 | EI6: 00:30 | EJ6: 0 | EL6: 09:00 | EM6: 17:00 | EN6: 00:30 | EO6: 0 | EQ6: 09:00 | ER6: 17:00 | ES6: 00:30 | ET6: 0 | EV6: 08:46 | EW6: 17:43 | EX6: 00:45 | EY6: 0.71 | FA6: 09:00 | FB6: 17:00 | FC6: 00:30 | FD6: 0 | FF6: 09:00 | FG6: 17:00 | FH6: 00:30 | FI6: 0 | FK6: 09:00 | FL6: 17:00 | FM6: 00:30 | FN6: 0 | FP6: 09:00 | FQ6: 17:30 | FR6: 00:39 | FS6: 0.34 | FU6: 09:00 | FV6: 17:00 | FW6: 00:30 | FX6: 0 | FZ6: 09:13 | GA6: 17:30 | GB6: 00:40 | GC6: 0.11 | GE6: 09:01 | GF6: 17:30 | GG6: 00:37 | GH6: 0.36 | GJ6: 08:56 | GK6: 17:30 | GL6: 00:38 | GM6: 0.43 | GO6: 09:00 | GP6: 17:00 | GQ6: 00:30 | GR6: 0 | GT6: 08:38 | GU6: 19:37 | GV6: 00:30 | GW6: 2.97
A7: 2026-01-28 | B7: 09:00 | C7: 17:00 | D7: 00:30 | E7: 0 | G7: 11:58 | H7: 17:34 | I7: 00:42 | J7: -2.59 | L7: 10:11 | M7: 17:28 | N7: 00:32 | O7: -0.74 | Q7: 09:53 | R7: 18:11 | S7: 00:30 | T7: 0.3 | V7: 09:18 | W7: 18:58 | X7: 00:43 | Y7: 1.43 | AA7: 09:00 | AB7: 17:00 | AC7: 00:30 | AD7: 0 | AF7: 09:48 | AG7: 17:44 | AH7: 00:32 | AI7: -0.11 | AK7: 09:50 | AL7: 17:36 | AM7: 00:55 | AN7: -0.65 | AP7: 18:10 | AQ7: 17:30 | AR7: 00:30 | AS7: 15.33 | AU7: 09:28 | AV7: 18:43 | AW7: 00:43 | AX7: 1.03 | AZ7: 09:00 | BA7: 17:00 | BB7: 00:30 | BC7: 0 | BE7: 10:06 | BF7: 18:56 | BG7: 00:44 | BH7: 0.6 | BJ7: 09:00 | BK7: 17:00 | BL7: 00:30 | BM7: 0 | BO7: 09:00 | BP7: 17:00 | BQ7: 00:30 | BR7: 0 | BT7: 09:00 | BU7: 17:00 | BV7: 00:30 | BW7: 0 | BY7: 10:55 | BZ7: 17:43 | CA7: 00:39 | CB7: -1.35 | CD7: 09:00 | CE7: 17:00 | CF7: 00:30 | CG7: 0 | CI7: 09:00 | CJ7: 17:00 | CK7: 00:30 | CL7: 0 | CN7: 08:56 | CO7: 18:31 | CP7: 00:33 | CQ7: 1.55 | CS7: 08:32 | CT7: 17:30 | CU7: 00:32 | CV7: 0.92 | CX7: 09:00 | CY7: 17:00 | CZ7: 00:30 | DA7: 0 | DC7: 10:12 | DD7: 17:38 | DE7: 00:46 | DF7: -0.83 | DH7: 09:44 | DI7: 17:43 | DJ7: 00:34 | DK7: -0.1 | DM7: 09:52 | DN7: 17:28 | DO7: 00:35 | DP7: -0.48 | DR7: 09:00 | DS7: 17:00 | DT7: 00:30 | DU7: 0 | DW7: 09:11 | DX7: 17:30 | DY7: 00:37 | DZ7: 0.18 | EB7: 14:06 | EC7: 17:28 | ED7: 00:42 | EE7: -4.84 | EG7: 09:00 | EH7: 17:00 | EI7: 00:30 | EJ7: 0 | EL7: 09:00 | EM7: 17:00 | EN7: 00:30 | EO7: 0 | EQ7: 08:36 | ER7: 17:36 | ES7: 00:36 | ET7: 0.89 | EV7: 09:00 | EW7: 17:00 | EX7: 00:30 | EY7: 0 | FA7: 09:49 | FB7: 17:43 | FC7: 00:34 | FD7: -0.18 | FF7: 09:00 | FG7: 17:00 | FH7: 00:30 | FI7: 0 | FK7: 09:53 | FL7: 17:39 | FM7: 00:41 | FN7: -0.41 | FP7: 09:00 | FQ7: 17:00 | FR7: 00:30 | FS7: 0 | FU7: 09:08 | FV7: 17:44 | FW7: 00:40 | FX7: 0.43 | FZ7: 09:50 | GA7: 17:35 | GB7: 00:37 | GC7: -0.37 | GE7: 09:50 | GF7: 17:36 | GG7: 00:34 | GH7: -0.3 | GJ7: 09:00 | GK7: 17:00 | GL7: 00:30 | GM7: 0 | GO7: 09:00 | GP7: 17:00 | GQ7: 00:30 | GR7: 0 | GT7: 10:09 | GU7: 17:33 | GV7: 00:34 | GW7: -0.67
A8: 2026-01-29 | B8: 09:00 | C8: 17:00 | D8: 00:30 | E8: 0 | G8: 08:56 | H8: 17:38 | I8: 00:34 | J8: 0.64 | L8: 08:51 | M8: 17:29 | N8: 00:44 | O8: 0.41 | Q8: 08:46 | R8: 18:08 | S8: 00:37 | T8: 1.26 | V8: 08:54 | W8: 17:30 | X8: 00:45 | Y8: 0.34 | AA8: 09:00 | AB8: 17:00 | AC8: 00:30 | AD8: 0 | AF8: 09:21 | AG8: 17:42 | AH8: 00:38 | AI8: 0.21 | AK8: 08:54 | AL8: 17:30 | AM8: 00:36 | AN8: 0.5 | AP8: 09:08 | AQ8: 17:34 | AR8: 00:32 | AS8: 0.4 | AU8: 09:21 | AV8: 17:30 | AW8: 00:33 | AX8: 0.08 | AZ8: 08:57 | BA8: 17:48 | BB8: 00:32 | BC8: 0.82 | BE8: 08:55 | BF8: 18:02 | BG8: 00:46 | BH8: 0.85 | BJ8: 09:11 | BK8: 17:49 | BL8: 00:45 | BM8: 0.38 | BO8: 09:00 | BP8: 17:00 | BQ8: 00:30 | BR8: 0 | BT8: 09:00 | BU8: 17:00 | BV8: 00:30 | BW8: 0 | BY8: 09:07 | BZ8: 17:35 | CA8: 00:44 | CB8: 0.24 | CD8: 08:52 | CE8: 17:41 | CF8: 00:00 | CG8: 0.71 | CI8: 09:00 | CJ8: 17:00 | CK8: 00:30 | CL8: 0 | CN8: 07:46 | CO8: 19:13 | CP8: 00:36 | CQ8: 3.36 | CS8: 09:02 | CT8: 17:30 | CU8: 00:34 | CV8: 0.4 | CX8: 09:23 | CY8: 17:30 | CZ8: 00:33 | DA8: 0.06 | DC8: 08:51 | DD8: 17:07 | DE8: 00:45 | DF8: 0.01 | DH8: 09:45 | DI8: 17:30 | DJ8: 00:35 | DK8: -0.33 | DM8: 08:51 | DN8: 17:44 | DO8: 00:44 | DP8: 0.66 | DR8: 13:57 | DS8: 17:41 | DT8: 00:31 | DU8: -4.28 | DW8: 09:18 | DX8: 17:36 | DY8: 00:33 | DZ8: 0.24 | EB8: 09:00 | EC8: 17:00 | ED8: 00:30 | EE8: 0 | EG8: 09:52 | EH8: 17:27 | EI8: 00:33 | EJ8: -0.46 | EL8: 09:06 | EM8: 17:41 | EN8: 00:43 | EO8: 0.36 | EQ8: 08:35 | ER8: 17:54 | ES8: 00:33 | ET8: 1.26 | EV8: 08:53 | EW8: 17:32 | EX8: 00:44 | EY8: 0.41 | FA8: 08:30 | FB8: 17:30 | FC8: 00:41 | FD8: 0.81 | FF8: 09:00 | FG8: 17:00 | FH8: 00:30 | FI8: 0 | FK8: 08:49 | FL8: 17:35 | FM8: 00:44 | FN8: 0.54 | FP8: 08:47 | FQ8: 17:42 | FR8: 00:31 | FS8: 0.89 | FU8: 09:02 | FV8: 17:30 | FW8: 00:32 | FX8: 0.42 | FZ8: 09:51 | GA8: 17:44 | GB8: 00:42 | GC8: -0.31 | GE8: 09:02 | GF8: 17:35 | GG8: 00:31 | GH8: 0.53 | GJ8: 08:57 | GK8: 17:43 | GL8: 00:33 | GM8: 0.72 | GO8: 09:00 | GP8: 17:00 | GQ8: 00:30 | GR8: 0 | GT8: 08:36 | GU8: 18:09 | GV8: 00:43 | GW8: 1.33
A9: 2026-01-30 | B9: 09:00 | C9: 17:00 | D9: 00:30 | E9: 0 | G9: 08:51 | H9: 17:43 | I9: 00:40 | J9: 0.69 | L9: 09:16 | M9: 17:33 | N9: 00:43 | O9: 0.07 | Q9: 09:04 | R9: 17:52 | S9: 00:33 | T9: 0.75 | V9: 09:00 | W9: 17:00 | X9: 00:30 | Y9: 0 | AA9: 09:35 | AB9: 17:41 | AC9: 00:35 | AD9: 0 | AF9: 09:00 | AG9: 17:00 | AH9: 00:30 | AI9: 0 | AK9: 09:00 | AL9: 17:00 | AM9: 00:30 | AN9: 0 | AP9: 09:00 | AQ9: 17:00 | AR9: 00:30 | AS9: 0 | AU9: 09:00 | AV9: 17:00 | AW9: 00:30 | AX9: 0 | AZ9: 09:00 | BA9: 17:00 | BB9: 00:30 | BC9: 0 | BE9: 08:51 | BF9: 18:42 | BG9: 00:44 | BH9: 1.62 | BJ9: 08:59 | BK9: 17:32 | BL9: 00:31 | BM9: 0.53 | BO9: 09:00 | BP9: 17:00 | BQ9: 00:30 | BR9: 0 | BT9: 09:00 | BU9: 17:00 | BV9: 00:30 | BW9: 0 | BY9: 09:00 | BZ9: 17:00 | CA9: 00:30 | CB9: 0 | CD9: 08:47 | CE9: 17:34 | CF9: 00:39 | CG9: 0.63 | CI9: 09:00 | CJ9: 17:00 | CK9: 00:30 | CL9: 0 | CN9: 09:00 | CO9: 19:28 | CP9: 00:38 | CQ9: 2.33 | CS9: 09:00 | CT9: 17:00 | CU9: 00:30 | CV9: 0 | CX9: 09:00 | CY9: 17:00 | CZ9: 00:30 | DA9: 0 | DC9: 09:17 | DD9: 17:28 | DE9: 00:41 | DF9: 0 | DH9: 09:50 | DI9: 17:57 | DJ9: 00:38 | DK9: 0 | DM9: 09:12 | DN9: 17:29 | DO9: 00:33 | DP9: 0.25 | DR9: 08:53 | DS9: 17:33 | DT9: 00:38 | DU9: 0.53 | DW9: 09:00 | DX9: 17:00 | DY9: 00:30 | DZ9: 0 | EB9: 09:00 | EC9: 17:00 | ED9: 00:30 | EE9: 0 | EG9: 09:55 | EH9: 17:58 | EI9: 00:32 | EJ9: 0.01 | EL9: 09:11 | EM9: 17:33 | EN9: 00:43 | EO9: 0.14 | EQ9: 08:21 | ER9: 17:30 | ES9: 00:39 | ET9: 1 | EV9: 09:00 | EW9: 17:00 | EX9: 00:30 | EY9: 0 | FA9: 09:00 | FB9: 17:00 | FC9: 00:30 | FD9: 0 | FF9: 09:00 | FG9: 17:00 | FH9: 00:30 | FI9: 0 | FK9: 09:00 | FL9: 17:32 | FM9: 00:32 | FN9: 0.48 | FP9: 08:59 | FQ9: 17:29 | FR9: 00:33 | FS9: 0.47 | FU9: 09:00 | FV9: 17:00 | FW9: 00:30 | FX9: 0 | FZ9: 09:00 | GA9: 17:00 | GB9: 00:30 | GC9: 0 | GE9: 09:00 | GF9: 17:00 | GG9: 00:30 | GH9: 0 | GJ9: 09:04 | GK9: 17:38 | GL9: 00:30 | GM9: 0.56 | GO9: 09:00 | GP9: 17:00 | GQ9: 00:30 | GR9: 0 | GT9: 08:35 | GU9: 17:52 | GV9: 00:44 | GW9: 1.03
A10: 2026-02-02 | B10: 09:00 | C10: 17:00 | D10: 00:30 | E10: 0 | G10: 08:33 | H10: 17:44 | I10: 00:32 | J10: 1.15 | L10: 09:01 | M10: 17:13 | N10: 00:39 | O10: 0.06 | Q10: 08:52 | R10: 17:34 | S10: 00:34 | T10: 0.62 | V10: 09:00 | W10: 17:00 | X10: 00:30 | Y10: 0 | AA10: 12:21 | AB10: 17:27 | AC10: 00:43 | AD10: -3.12 | AF10: 09:19 | AG10: 17:41 | AH10: 00:38 | AI10: 0.21 | AK10: 09:00 | AL10: 17:00 | AM10: 00:30 | AN10: 0 | AP10: 09:24 | AQ10: 17:40 | AR10: 00:37 | AS10: 0.15 | AU10: 09:24 | AV10: 18:45 | AW10: 00:32 | AX10: 1.33 | AZ10: 09:00 | BA10: 17:00 | BB10: 00:30 | BC10: 0 | BE10: 08:52 | BF10: 17:47 | BG10: 00:38 | BH10: 0.78 | BJ10: 09:01 | BK10: 17:35 | BL10: 00:33 | BM10: 0.51 | BO10: 09:00 | BP10: 17:00 | BQ10: 00:30 | BR10: 0 | BT10: 11:42 | BU10: 17:35 | BV10: 00:37 | BW10: -2.24 | BY10: 08:56 | BZ10: 17:39 | CA10: 00:38 | CB10: 0.58 | CD10: 09:01 | CE10: 17:30 | CF10: 00:37 | CG10: 0.36 | CI10: 09:00 | CJ10: 17:00 | CK10: 00:30 | CL10: 0 | CN10: 07:46 | CO10: 17:47 | CP10: 00:34 | CQ10: 1.95 | CS10: 09:00 | CT10: 17:00 | CU10: 00:30 | CV10: 0 | CX10: 09:17 | CY10: 17:30 | CZ10: 00:35 | DA10: 0.12 | DC10: 09:00 | DD10: 17:00 | DE10: 00:30 | DF10: 0 | DH10: 10:44 | DI10: 17:33 | DJ10: 00:45 | DK10: -1.42 | DM10: 08:50 | DN10: 17:31 | DO10: 00:43 | DP10: 0.46 | DR10: 09:00 | DS10: 17:00 | DT10: 00:30 | DU10: 0 | DW10: 09:17 | DX10: 17:38 | DY10: 00:37 | DZ10: 0.22 | EB10: 09:00 | EC10: 17:00 | ED10: 00:30 | EE10: 0 | EG10: 09:00 | EH10: 17:00 | EI10: 00:30 | EJ10: 0 | EL10: 09:07 | EM10: 17:41 | EN10: 00:41 | EO10: 0.38 | EQ10: 08:26 | ER10: 17:45 | ES10: 00:31 | ET10: 1.3 | EV10: 09:00 | EW10: 17:00 | EX10: 00:30 | EY10: 0 | FA10: 09:00 | FB10: 17:00 | FC10: 00:30 | FD10: 0 | FF10: 09:00 | FG10: 17:00 | FH10: 00:30 | FI10: 0 | FK10: 08:52 | FL10: 17:38 | FM10: 00:37 | FN10: 0.64 | FP10: 09:16 | FQ10: 18:09 | FR10: 00:45 | FS10: 0.64 | FU10: 09:01 | FV10: 17:41 | FW10: 00:35 | FX10: 0.58 | FZ10: 09:25 | GA10: 17:38 | GB10: 00:40 | GC10: 0.05 | GE10: 09:05 | GF10: 17:38 | GG10: 00:45 | GH10: 0.3 | GJ10: 09:05 | GK10: 17:48 | GL10: 00:42 | GM10: 0.51 | GO10: 08:15 | GP10: 17:26 | GQ10: 00:38 | GR10: 1.05 | GT10: 08:52 | GU10: 17:31 | GV10: 00:33 | GW10: 0.61
A11: 2026-02-03 | B11: 08:52 | C11: 17:31 | D11: 00:38 | E11: 0.51 | G11: 09:00 | H11: 17:38 | I11: 00:33 | J11: 0.6 | L11: 09:11 | M11: 17:26 | N11: 00:39 | O11: 0.1 | Q11: 09:00 | R11: 17:00 | S11: 00:30 | T11: 0 | V11: 09:13 | W11: 18:40 | X11: 00:31 | Y11: 1.42 | AA11: 09:00 | AB11: 17:00 | AC11: 00:30 | AD11: 0 | AF11: 09:21 | AG11: 17:36 | AH11: 00:44 | AI11: 0.02 | AK11: 09:00 | AL11: 17:00 | AM11: 00:30 | AN11: 0 | AP11: 09:00 | AQ11: 17:00 | AR11: 00:30 | AS11: 0 | AU11: 09:26 | AV11: 18:56 | AW11: 00:36 | AX11: 1.4 | AZ11: 09:00 | BA11: 17:00 | BB11: 00:30 | BC11: 0 | BE11: 08:54 | BF11: 17:42 | BG11: 00:32 | BH11: 0.77 | BJ11: 09:00 | BK11: 17:00 | BL11: 00:30 | BM11: 0 | BO11: 09:00 | BP11: 17:00 | BQ11: 00:30 | BR11: 0 | BT11: 09:00 | BU11: 17:00 | BV11: 00:30 | BW11: 0 | BY11: 09:07 | BZ11: 17:35 | CA11: 00:44 | CB11: 0.23 | CD11: 09:00 | CE11: 17:30 | CF11: 00:31 | CG11: 0.49 | CI11: 09:00 | CJ11: 17:00 | CK11: 00:30 | CL11: 0 | CN11: 08:53 | CO11: 17:30 | CP11: 00:40 | CQ11: 0.45 | CS11: 09:00 | CT11: 17:00 | CU11: 00:30 | CV11: 0 | CX11: 09:13 | CY11: 17:30 | CZ11: 00:32 | DA11: 0.24 | DC11: 09:00 | DD11: 17:00 | DE11: 00:30 | DF11: 0 | DH11: 09:12 | DI11: 17:30 | DJ11: 00:31 | DK11: 0.27 | DM11: 08:56 | DN11: 17:30 | DO11: 00:42 | DP11: 0.37 | DR11: 09:00 | DS11: 17:00 | DT11: 00:30 | DU11: 0 | DW11: 09:20 | DX11: 17:37 | DY11: 00:39 | DZ11: 0.14 | EB11: 09:00 | EC11: 17:00 | ED11: 00:30 | EE11: 0 | EG11: 09:00 | EH11: 17:00 | EI11: 00:30 | EJ11: 0 | EL11: 09:25 | EM11: 18:03 | EN11: 00:44 | EO11: 0.41 | EQ11: 09:00 | ER11: 17:00 | ES11: 00:30 | ET11: 0 | EV11: 09:15 | EW11: 17:51 | EX11: 00:33 | EY11: 0.55 | FA11: 09:00 | FB11: 17:00 | FC11: 00:30 | FD11: 0 | FF11: 09:00 | FG11: 17:00 | FH11: 00:30 | FI11: 0 | FK11: 08:55 | FL11: 17:38 | FM11: 00:34 | FN11: 0.66 | FP11: 09:00 | FQ11: 17:00 | FR11: 00:30 | FS11: 0 | FU11: 09:14 | FV11: 17:30 | FW11: 00:44 | FX11: 0.03 | FZ11: 11:35 | GA11: 17:31 | GB11: 00:43 | GC11: -2.28 | GE11: 09:07 | GF11: 17:39 | GG11: 00:30 | GH11: 0.53 | GJ11: 09:10 | GK11: 17:42 | GL11: 00:42 | GM11: 0.35 | GO11: 08:10 | GP11: 17:10 | GQ11: 00:43 | GR11: 0.79 | GT11: 09:00 | GU11: 17:45 | GV11: 00:41 | GW11: 0.56
A12: 2026-02-04 | B12: 08:53 | C12: 17:37 | D12: 00:34 | E12: 0.68 | G12: 09:06 | H12: 18:01 | I12: 00:42 | J12: 0.71 | L12: 09:33 | M12: 17:30 | N12: 00:39 | O12: -0.21 | Q12: 09:14 | R12: 18:24 | S12: 00:39 | T12: 1.02 | V12: 09:07 | W12: 17:51 | X12: 00:37 | Y12: 0.62 | AA12: 08:43 | AB12: 17:30 | AC12: 00:30 | AD12: 0.77 | AF12: 09:28 | AG12: 17:43 | AH12: 00:45 | AI12: 0 | AK12: 08:59 | AL12: 17:30 | AM12: 00:30 | AN12: 0.51 | AP12: 09:20 | AQ12: 17:30 | AR12: 00:37 | AS12: 0.04 | AU12: 09:12 | AV12: 18:23 | AW12: 00:41 | AX12: 1 | AZ12: 09:00 | BA12: 17:00 | BB12: 00:30 | BC12: 0 | BE12: 09:02 | BF12: 18:25 | BG12: 00:43 | BH12: 1.18 | BJ12: 09:03 | BK12: 17:49 | BL12: 00:44 | BM12: 0.53 | BO12: 09:00 | BP12: 17:00 | BQ12: 00:30 | BR12: 0 | BT12: 09:12 | BU12: 18:32 | BV12: 00:42 | BW12: 1.15 | BY12: 09:09 | BZ12: 18:01 | CA12: 00:40 | CB12: 0.71 | CD12: 09:07 | CE12: 17:30 | CF12: 00:38 | CG12: 0.23 | CI12: 18:47 | CJ12: 17:33 | CK12: 00:30 | CL12: 14.76 | CN12: 08:51 | CO12: 19:16 | CP12: 00:33 | CQ12: 2.36 | CS12: 09:00 | CT12: 17:00 | CU12: 00:30 | CV12: 0 | CX12: 09:16 | CY12: 17:30 | CZ12: 00:34 | DA12: 0.17 | DC12: 10:25 | DD12: 17:29 | DE12: 00:44 | DF12: -1.16 | DH12: 09:10 | DI12: 19:18 | DJ12: 00:35 | DK12: 2.04 | DM12: 08:59 | DN12: 17:31 | DO12: 00:35 | DP12: 0.45 | DR12: 09:00 | DS12: 17:00 | DT12: 00:30 | DU12: 0 | DW12: 09:24 | DX12: 17:30 | DY12: 00:39 | DZ12: -0.04 | EB12: 09:00 | EC12: 17:00 | ED12: 00:30 | EE12: 0 | EG12: 09:00 | EH12: 17:00 | EI12: 00:30 | EJ12: 0 | EL12: 09:19 | EM12: 17:40 | EN12: 00:43 | EO12: 0.14 | EQ12: 08:34 | ER12: 17:30 | ES12: 00:35 | ET12: 0.84 | EV12: 08:50 | EW12: 17:33 | EX12: 00:40 | EY12: 0.56 | FA12: 09:00 | FB12: 17:00 | FC12: 00:30 | FD12: 0 | FF12: 09:00 | FG12: 17:00 | FH12: 00:30 | FI12: 0 | FK12: 09:07 | FL12: 17:37 | FM12: 00:41 | FN12: 0.3 | FP12: 08:50 | FQ12: 17:45 | FR12: 00:36 | FS12: 0.83 | FU12: 09:00 | FV12: 17:00 | FW12: 00:30 | FX12: 0 | FZ12: 09:06 | GA12: 17:39 | GB12: 00:32 | GC12: 0.53 | GE12: 09:00 | GF12: 17:00 | GG12: 00:30 | GH12: 0 | GJ12: 08:55 | GK12: 17:42 | GL12: 00:38 | GM12: 0.66 | GO12: 08:33 | GP12: 17:46 | GQ12: 00:40 | GR12: 1.06 | GT12: 09:00 | GU12: 17:00 | GV12: 00:30 | GW12: 0
A13: 2026-02-05 | B13: 09:00 | C13: 17:00 | D13: 00:30 | E13: 0 | G13: 09:02 | H13: 17:40 | I13: 00:35 | J13: 0.54 | L13: 09:22 | M13: 17:31 | N13: 00:39 | O13: 0 | Q13: 09:03 | R13: 20:18 | S13: 00:37 | T13: 3.14 | V13: 08:49 | W13: 17:30 | X13: 00:44 | Y13: 0.44 | AA13: 08:40 | AB13: 17:30 | AC13: 00:39 | AD13: 0.67 | AF13: 09:22 | AG13: 17:35 | AH13: 00:37 | AI13: 0.12 | AK13: 08:54 | AL13: 17:30 | AM13: 00:32 | AN13: 0.56 | AP13: 09:26 | AQ13: 17:55 | AR13: 00:36 | AS13: 0.37 | AU13: 09:28 | AV13: 18:23 | AW13: 00:40 | AX13: 0.76 | AZ13: 09:00 | BA13: 17:00 | BB13: 00:30 | BC13: 0 | BE13: 09:06 | BF13: 17:39 | BG13: 00:32 | BH13: 0.52 | BJ13: 09:02 | BK13: 17:33 | BL13: 00:42 | BM13: 0.32 | BO13: 09:00 | BP13: 17:00 | BQ13: 00:30 | BR13: 0 | BT13: 15:06 | BU13: 17:36 | BV13: 00:33 | BW13: -5.54 | BY13: 09:09 | BZ13: 17:47 | CA13: 00:36 | CB13: 0.55 | CD13: 09:05 | CE13: 17:32 | CF13: 00:40 | CG13: 0.3 | CI13: 09:00 | CJ13: 17:00 | CK13: 00:30 | CL13: 0 | CN13: 08:45 | CO13: 21:02 | CP13: 00:39 | CQ13: 4.15 | CS13: 09:00 | CT13: 17:00 | CU13: 00:30 | CV13: 0 | CX13: 09:11 | CY13: 17:30 | CZ13: 00:40 | DA13: 0.15 | DC13: 09:22 | DD13: 17:34 | DE13: 00:33 | DF13: 0.15 | DH13: 09:17 | DI13: 17:30 | DJ13: 00:40 | DK13: 0.04 | DM13: 08:58 | DN13: 17:32 | DO13: 00:41 | DP13: 0.38 | DR13: 09:00 | DS13: 17:00 | DT13: 00:30 | DU13: 0 | DW13: 09:00 | DX13: 17:00 | DY13: 00:30 | DZ13: 0 | EB13: 09:00 | EC13: 17:00 | ED13: 00:30 | EE13: 0 | EG13: 09:00 | EH13: 17:00 | EI13: 00:30 | EJ13: 0 | EL13: 09:21 | EM13: 17:30 | EN13: 00:35 | EO13: 0.06 | EQ13: 08:38 | ER13: 17:53 | ES13: 00:41 | ET13: 1.07 | EV13: 09:13 | EW13: 17:30 | EX13: 00:39 | EY13: 0.12 | FA13: 09:00 | FB13: 17:00 | FC13: 00:30 | FD13: 0 | FF13: 09:00 | FG13: 17:00 | FH13: 00:30 | FI13: 0 | FK13: 08:51 | FL13: 17:39 | FM13: 00:33 | FN13: 0.75 | FP13: 08:57 | FQ13: 17:36 | FR13: 00:34 | FS13: 0.58 | FU13: 09:00 | FV13: 17:30 | FW13: 00:41 | FX13: 0.31 | FZ13: 09:05 | GA13: 17:37 | GB13: 00:34 | GC13: 0.46 | GE13: 09:00 | GF13: 17:00 | GG13: 00:30 | GH13: 0 | GJ13: 08:56 | GK13: 17:47 | GL13: 00:34 | GM13: 0.79 | GO13: 08:42 | GP13: 17:29 | GQ13: 00:42 | GR13: 0.58 | GT13: 08:59 | GU13: 17:42 | GV13: 00:37 | GW13: 0.59
A14: 2026-02-06 | B14: 08:57 | C14: 17:32 | D14: 00:43 | E14: 0.36 | G14: 08:52 | H14: 17:46 | I14: 00:39 | J14: 0.76 | L14: 09:03 | M14: 17:42 | N14: 00:40 | O14: 0.48 | Q14: 09:00 | R14: 17:00 | S14: 00:30 | T14: 0 | V14: 09:00 | W14: 17:00 | X14: 00:30 | Y14: 0 | AA14: 09:00 | AB14: 17:00 | AC14: 00:30 | AD14: 0 | AF14: 09:00 | AG14: 17:00 | AH14: 00:30 | AI14: 0 | AK14: 09:00 | AL14: 17:00 | AM14: 00:30 | AN14: 0 | AP14: 09:00 | AQ14: 17:00 | AR14: 00:30 | AS14: 0 | AU14: 09:21 | AV14: 18:23 | AW14: 00:40 | AX14: 0.86 | AZ14: 09:00 | BA14: 17:00 | BB14: 00:30 | BC14: 0 | BE14: 08:54 | BF14: 18:06 | BG14: 00:44 | BH14: 0.96 | BJ14: 09:04 | BK14: 17:38 | BL14: 00:40 | BM14: 0.4 | BO14: 09:00 | BP14: 17:00 | BQ14: 00:30 | BR14: 0 | BT14: 09:00 | BU14: 17:00 | BV14: 00:30 | BW14: 0 | BY14: 09:06 | BZ14: 17:50 | CA14: 00:38 | CB14: 0.59 | CD14: 08:50 | CE14: 17:32 | CF14: 00:34 | CG14: 0.63 | CI14: 09:00 | CJ14: 17:00 | CK14: 00:30 | CL14: 0 | CN14: 09:08 | CO14: 18:14 | CP14: 00:44 | CQ14: 0.87 | CS14: 09:00 | CT14: 17:00 | CU14: 00:30 | CV14: 0 | CX14: 09:20 | CY14: 17:33 | CZ14: 00:45 | DA14: -0.04 | DC14: 08:47 | DD14: 16:55 | DE14: 00:33 | DF14: 0.08 | DH14: 09:00 | DI14: 17:00 | DJ14: 00:30 | DK14: 0 | DM14: 08:54 | DN14: 17:33 | DO14: 00:32 | DP14: 0.61 | DR14: 08:57 | DS14: 17:31 | DT14: 00:42 | DU14: 0.36 | DW14: 09:15 | DX14: 17:31 | DY14: 00:34 | DZ14: 0.21 | EB14: 09:00 | EC14: 17:00 | ED14: 00:30 | EE14: 0 | EG14: 09:00 | EH14: 17:00 | EI14: 00:30 | EJ14: 0 | EL14: 09:00 | EM14: 17:00 | EN14: 00:30 | EO14: 0 | EQ14: 08:50 | ER14: 17:30 | ES14: 00:42 | ET14: 0.45 | EV14: 09:00 | EW14: 17:00 | EX14: 00:30 | EY14: 0 | FA14: 09:00 | FB14: 17:00 | FC14: 00:30 | FD14: 0 | FF14: 09:00 | FG14: 17:00 | FH14: 00:30 | FI14: 0 | FK14: 09:00 | FL14: 17:00 | FM14: 00:30 | FN14: 0 | FP14: 09:07 | FQ14: 17:32 | FR14: 00:41 | FS14: 0.24 | FU14: 09:04 | FV14: 17:30 | FW14: 00:41 | FX14: 0.24 | FZ14: 09:00 | GA14: 17:00 | GB14: 00:30 | GC14: 0 | GE14: 08:57 | GF14: 17:31 | GG14: 00:43 | GH14: 0.35 | GJ14: 08:54 | GK14: 17:32 | GL14: 00:41 | GM14: 0.46 | GO14: 08:45 | GP14: 17:26 | GQ14: 00:33 | GR14: 0.64 | GT14: 08:56 | GU14: 17:50 | GV14: 00:46 | GW14: 0.63
A15: 2026-02-09 | B15: 09:00 | C15: 17:00 | D15: 00:30 | E15: 0 | G15: 08:57 | H15: 17:39 | I15: 00:37 | J15: 0.59 | L15: 09:00 | M15: 17:00 | N15: 00:30 | O15: 0 | Q15: 09:10 | R15: 18:26 | S15: 00:41 | T15: 1.07 | V15: 09:00 | W15: 17:00 | X15: 00:30 | Y15: 0 | AA15: 08:27 | AB15: 17:38 | AC15: 00:36 | AD15: 1.08 | AF15: 09:47 | AG15: 17:27 | AH15: 00:42 | AI15: -0.53 | AK15: 09:03 | AL15: 17:30 | AM15: 00:43 | AN15: 0.22 | AP15: 09:00 | AQ15: 17:00 | AR15: 00:30 | AS15: 0 | AU15: 09:23 | AV15: 18:22 | AW15: 00:36 | AX15: 0.87 | AZ15: 09:00 | BA15: 17:00 | BB15: 00:30 | BC15: 0 | BE15: 09:06 | BF15: 17:32 | BG15: 00:43 | BH15: 0.22 | BJ15: 08:59 | BK15: 17:38 | BL15: 00:43 | BM15: 0.42 | BO15: 09:00 | BP15: 17:00 | BQ15: 00:30 | BR15: 0 | BT15: 09:00 | BU15: 17:00 | BV15: 00:30 | BW15: 0 | BY15: 12:26 | BZ15: 17:31 | CA15: 00:31 | CB15: -2.92 | CD15: 08:54 | CE15: 17:30 | CF15: 00:46 | CG15: 0.33 | CI15: 09:00 | CJ15: 17:00 | CK15: 00:30 | CL15: 0 | CN15: 07:43 | CO15: 18:36 | CP15: 00:41 | CQ15: 2.7 | CS15: 09:00 | CT15: 17:00 | CU15: 00:30 | CV15: 0 | CX15: 18:50 | CY15: 17:42 | CZ15: 00:30 | DA15: 14.87 | DC15: 08:43 | DD15: 16:58 | DE15: 00:42 | DF15: 0.04 | DH15: 09:02 | DI15: 17:30 | DJ15: 00:45 | DK15: 0.21 | DM15: 08:51 | DN15: 17:30 | DO15: 00:41 | DP15: 0.47 | DR15: 09:04 | DS15: 17:37 | DT15: 00:44 | DU15: 0.33 | DW15: 09:00 | DX15: 17:00 | DY15: 00:30 | DZ15: 0 | EB15: 09:00 | EC15: 17:00 | ED15: 00:30 | EE15: 0 | EG15: 11:43 | EH15: 17:43 | EI15: 00:40 | EJ15: -2.17 | EL15: 09:00 | EM15: 17:00 | EN15: 00:30 | EO15: 0 | EQ15: 08:26 | ER15: 17:30 | ES15: 00:33 | ET15: 1.01 | EV15: 09:00 | EW15: 17:00 | EX15: 00:30 | EY15: 0 | FA15: 09:00 | FB15: 17:00 | FC15: 00:30 | FD15: 0 | FF15: 09:00 | FG15: 17:00 | FH15: 00:30 | FI15: 0 | FK15: 08:46 | FL15: 17:38 | FM15: 00:36 | FN15: 0.78 | FP15: 08:57 | FQ15: 17:37 | FR15: 00:35 | FS15: 0.57 | FU15: 09:05 | FV15: 17:30 | FW15: 00:37 | FX15: 0.29 | FZ15: 09:14 | GA15: 17:42 | GB15: 00:39 | GC15: 0.31 | GE15: 08:59 | GF15: 17:26 | GG15: 00:39 | GH15: 0.3 | GJ15: 08:59 | GK15: 17:39 | GL15: 00:46 | GM15: 0.4 | GO15: 08:48 | GP15: 17:28 | GQ15: 00:44 | GR15: 0.43 | GT15: 08:36 | GU15: 18:50 | GV15: 00:39 | GW15: 2.07
A16: 2026-02-10 | B16: 11:06 | C16: 17:42 | D16: 00:36 | E16: -1.5 | G16: 09:02 | H16: 17:31 | I16: 00:39 | J16: 0.33 | L16: 09:00 | M16: 17:00 | N16: 00:30 | O16: 0 | Q16: 08:52 | R16: 19:10 | S16: 00:33 | T16: 2.24 | V16: 09:00 | W16: 17:00 | X16: 00:30 | Y16: 0 | AA16: 08:37 | AB16: 17:22 | AC16: 00:32 | AD16: 0.72 | AF16: 09:50 | AG16: 17:39 | AH16: 00:39 | AI16: -0.33 | AK16: 09:02 | AL16: 17:30 | AM16: 00:41 | AN16: 0.28 | AP16: 09:00 | AQ16: 17:00 | AR16: 00:30 | AS16: 0 | AU16: 09:03 | AV16: 18:23 | AW16: 00:39 | AX16: 1.18 | AZ16: 08:59 | BA16: 18:14 | BB16: 00:43 | BC16: 1.04 | BE16: 09:00 | BF16: 17:31 | BG16: 00:45 | BH16: 0.27 | BJ16: 09:02 | BK16: 17:37 | BL16: 00:31 | BM16: 0.58 | BO16: 09:00 | BP16: 17:00 | BQ16: 00:30 | BR16: 0 | BT16: 09:09 | BU16: 17:39 | BV16: 00:33 | BW16: 0.44 | BY16: 09:08 | BZ16: 17:43 | CA16: 00:44 | CB16: 0.37 | CD16: 09:15 | CE16: 17:30 | CF16: 00:35 | CG16: 0.16 | CI16: 09:00 | CJ16: 17:00 | CK16: 00:30 | CL16: 0 | CN16: 08:29 | CO16: 19:11 | CP16: 00:32 | CQ16: 2.66 | CS16: 10:32 | CT16: 17:43 | CU16: 00:31 | CV16: -0.82 | CX16: 11:06 | CY16: 17:39 | CZ16: 00:39 | DA16: -1.6 | DC16: 08:56 | DD16: 17:00 | DE16: 00:32 | DF16: 0.05 | DH16: 09:16 | DI16: 17:30 | DJ16: 00:43 | DK16: 0.01 | DM16: 08:56 | DN16: 17:41 | DO16: 00:39 | DP16: 0.62 | DR16: 08:55 | DS16: 17:37 | DT16: 00:34 | DU16: 0.64 | DW16: 09:15 | DX16: 17:34 | DY16: 00:40 | DZ16: 0.14 | EB16: 09:00 | EC16: 17:00 | ED16: 00:30 | EE16: 0 | EG16: 09:00 | EH16: 17:00 | EI16: 00:30 | EJ16: 0 | EL16: 09:00 | EM16: 17:00 | EN16: 00:30 | EO16: 0 | EQ16: 09:00 | ER16: 17:00 | ES16: 00:30 | ET16: 0 | EV16: 08:48 | EW16: 17:23 | EX16: 00:31 | EY16: 0.56 | FA16: 09:00 | FB16: 17:00 | FC16: 00:30 | FD16: 0 | FF16: 09:00 | FG16: 17:00 | FH16: 00:30 | FI16: 0 | FK16: 08:58 | FL16: 17:37 | FM16: 00:36 | FN16: 0.56 | FP16: 08:58 | FQ16: 17:38 | FR16: 00:45 | FS16: 0.43 | FU16: 09:00 | FV16: 17:30 | FW16: 00:32 | FX16: 0.45 | FZ16: 09:00 | GA16: 17:00 | GB16: 00:30 | GC16: 0 | GE16: 09:00 | GF16: 17:00 | GG16: 00:30 | GH16: 0 | GJ16: 08:58 | GK16: 17:12 | GL16: 00:33 | GM16: 0.2 | GO16: 08:32 | GP16: 17:30 | GQ16: 00:39 | GR16: 0.79 | GT16: 08:47 | GU16: 19:10 | GV16: 00:37 | GW16: 2.27
A17: 2026-02-11 | B17: 08:46 | C17: 17:41 | D17: 00:43 | E17: 0.69 | G17: 09:03 | H17: 17:30 | I17: 00:31 | J17: 0.43 | L17: 09:00 | M17: 17:00 | N17: 00:30 | O17: 0 | Q17: 08:42 | R17: 17:44 | S17: 00:40 | T17: 0.86 | V17: 09:00 | W17: 17:00 | X17: 00:30 | Y17: 0 | AA17: 08:39 | AB17: 17:41 | AC17: 00:32 | AD17: 0.99 | AF17: 09:45 | AG17: 17:43 | AH17: 00:31 | AI17: -0.05 | AK17: 09:00 | AL17: 17:00 | AM17: 00:30 | AN17: 0 | AP17: 09:00 | AQ17: 17:00 | AR17: 00:30 | AS17: 0 | AU17: 09:25 | AV17: 18:24 | AW17: 00:39 | AX17: 0.84 | AZ17: 09:02 | BA17: 18:37 | BB17: 00:35 | BC17: 1.51 | BE17: 08:59 | BF17: 17:42 | BG17: 00:43 | BH17: 0.49 | BJ17: 09:00 | BK17: 17:00 | BL17: 00:30 | BM17: 0 | BO17: 08:26 | BP17: 17:30 | BQ17: 00:39 | BR17: 0.92 | BT17: 09:00 | BU17: 17:00 | BV17: 00:30 | BW17: 0 | BY17: 09:09 | BZ17: 18:48 | CA17: 00:45 | CB17: 1.38 | CD17: 08:59 | CE17: 17:35 | CF17: 00:34 | CG17: 0.53 | CI17: 09:00 | CJ17: 17:00 | CK17: 00:30 | CL17: 0 | CN17: 08:59 | CO17: 18:38 | CP17: 00:32 | CQ17: 1.63 | CS17: 07:00 | CT17: 18:59 | CU17: 00:31 | CV17: 3.97 | CX17: 11:00 | CY17: 17:25 | CZ17: 00:39 | DA17: -1.74 | DC17: 08:56 | DD17: 17:28 | DE17: 00:39 | DF17: 0.37 | DH17: 09:00 | DI17: 17:00 | DJ17: 00:30 | DK17: 0 | DM17: 09:11 | DN17: 17:41 | DO17: 00:42 | DP17: 0.31 | DR17: 09:02 | DS17: 18:33 | DT17: 00:38 | DU17: 1.37 | DW17: 08:52 | DX17: 17:39 | DY17: 00:31 | DZ17: 0.77 | EB17: 09:00 | EC17: 17:00 | ED17: 00:30 | EE17: 0 | EG17: 09:00 | EH17: 17:00 | EI17: 00:30 | EJ17: 0 | EL17: 09:16 | EM17: 17:46 | EN17: 00:33 | EO17: 0.45 | EQ17: 08:30 | ER17: 17:42 | ES17: 00:42 | ET17: 1 | EV17: 09:00 | EW17: 17:00 | EX17: 00:30 | EY17: 0 | FA17: 09:36 | FB17: 19:14 | FC17: 00:43 | FD17: 1.41 | FF17: 09:00 | FG17: 17:00 | FH17: 00:30 | FI17: 0 | FK17: 08:55 | FL17: 17:39 | FM17: 00:45 | FN17: 0.49 | FP17: 09:01 | FQ17: 17:37 | FR17: 00:41 | FS17: 0.41 | FU17: 09:01 | FV17: 17:34 | FW17: 00:32 | FX17: 0.52 | FZ17: 09:04 | GA17: 17:36 | GB17: 00:45 | GC17: 0.29 | GE17: 09:00 | GF17: 17:00 | GG17: 00:30 | GH17: 0 | GJ17: 08:55 | GK17: 17:43 | GL17: 00:39 | GM17: 0.64 | GO17: 07:59 | GP17: 17:23 | GQ17: 00:41 | GR17: 1.22 | GT17: 08:12 | GU17: 17:46 | GV17: 00:36 | GW17: 1.46
... A20: 2026-02-16 | B20: 08:51 | C20: 17:35 | D20: 00:40 | E20: 0.56 | G20: 08:54 | H20: 17:36 | I20: 00:44 | J20: 0.48 | L20: 08:51 | M20: 17:30 | N20: 00:42 | O20: 0.44 | Q20: 08:54 | R20: 17:56 | S20: 00:33 | T20: 0.99 | V20: 09:00 | W20: 17:00 | X20: 00:30 | Y20: 0 | AA20: 08:54 | AB20: 17:27 | AC20: 00:33 | AD20: 0.51 | AF20: 09:19 | AG20: 17:38 | AH20: 00:38 | AI20: 0.19 | AK20: 08:57 | AL20: 17:30 | AM20: 00:42 | AN20: 0.35 | AP20: 09:00 | AQ20: 17:00 | AR20: 00:30 | AS20: 0 | AU20: 09:23 | AV20: 17:30 | AW20: 00:32 | AX20: 0.07 | AZ20: 09:06 | BA20: 18:39 | BB20: 00:44 | BC20: 1.32 | BE20: 09:00 | BF20: 17:00 | BG20: 00:30 | BH20: 0 | BJ20: 09:00 | BK20: 17:32 | BL20: 00:34 | BM20: 0.47 | BO20: 08:52 | BP20: 17:30 | BQ20: 00:34 | BR20: 0.57 | BT20: 09:00 | BU20: 17:00 | BV20: 00:30 | BW20: 0 | BY20: 09:13 | BZ20: 17:57 | CA20: 00:41 | CB20: 0.53 | CD20: 08:54 | CE20: 17:37 | CF20: 00:37 | CG20: 0.59 | CI20: 09:00 | CJ20: 17:00 | CK20: 00:30 | CL20: 0 | CN20: 08:58 | CO20: 19:30 | CP20: 00:45 | CQ20: 2.29 | CS20: 09:00 | CT20: 17:00 | CU20: 00:30 | CV20: 0 | CX20: 15:09 | CY20: 17:35 | CZ20: 00:45 | DA20: -5.8 | DC20: 08:52 | DD20: 17:30 | DE20: 00:39 | DF20: 0.48 | DH20: 11:06 | DI20: 17:38 | DJ20: 00:39 | DK20: -1.61 | DM20: 09:00 | DN20: 17:00 | DO20: 00:30 | DP20: 0 | DR20: 09:00 | DS20: 17:30 | DT20: 00:34 | DU20: 0.43 | DW20: 09:36 | DX20: 17:37 | DY20: 00:45 | DZ20: -0.24 | EB20: 09:00 | EC20: 17:00 | ED20: 00:30 | EE20: 0 | EG20: 09:00 | EH20: 17:00 | EI20: 00:30 | EJ20: 0 | EL20: 09:09 | EM20: 17:34 | EN20: 00:32 | EO20: 0.39 | EQ20: 09:00 | ER20: 17:00 | ES20: 00:30 | ET20: 0 | EV20: 08:51 | EW20: 17:27 | EX20: 00:39 | EY20: 0.45 | FA20: 09:00 | FB20: 17:00 | FC20: 00:30 | FD20: 0 | FF20: 09:13 | FG20: 19:05 | FH20: 00:41 | FI20: 1.69 | FK20: 08:59 | FL20: 17:36 | FM20: 00:45 | FN20: 0.38 | FP20: 09:11 | FQ20: 17:36 | FR20: 00:40 | FS20: 0.26 | FU20: 09:00 | FV20: 17:00 | FW20: 00:30 | FX20: 0 | FZ20: 09:13 | GA20: 17:38 | GB20: 00:42 | GC20: 0.22 | GE20: 09:33 | GF20: 17:27 | GG20: 00:44 | GH20: -0.34 | GJ20: 10:11 | GK20: 17:43 | GL20: 00:43 | GM20: -0.67 | GO20: 09:00 | GP20: 17:00 | GQ20: 00:30 | GR20: 0 | GT20: 09:02 | GU20: 17:57 | GV20: 00:40 | GW20: 0.75
A21: 2026-02-17 | B21: 09:00 | C21: 17:00 | D21: 00:30 | E21: 0 | G21: 08:50 | H21: 17:30 | I21: 00:38 | J21: 0.53 | L21: 09:00 | M21: 17:00 | N21: 00:30 | O21: 0 | Q21: 08:58 | R21: 17:30 | S21: 00:45 | T21: 0.28 | V21: 08:57 | W21: 17:28 | X21: 00:38 | Y21: 0.38 | AA21: 09:00 | AB21: 17:00 | AC21: 00:30 | AD21: 0 | AF21: 09:18 | AG21: 17:38 | AH21: 00:37 | AI21: 0.21 | AK21: 08:48 | AL21: 17:30 | AM21: 00:38 | AN21: 0.56 | AP21: 09:03 | AQ21: 17:30 | AR21: 00:33 | AS21: 0.4 | AU21: 09:30 | AV21: 18:48 | AW21: 00:33 | AX21: 1.26 | AZ21: 09:06 | BA21: 18:28 | BB21: 00:44 | BC21: 1.13 | BE21: 09:00 | BF21: 17:00 | BG21: 00:30 | BH21: 0 | BJ21: 09:00 | BK21: 17:00 | BL21: 00:30 | BM21: 0 | BO21: 08:02 | BP21: 17:28 | BQ21: 00:34 | BR21: 1.36 | BT21: 09:00 | BU21: 17:00 | BV21: 00:30 | BW21: 0 | BY21: 09:33 | BZ21: 17:35 | CA21: 00:44 | CB21: -0.21 | CD21: 08:53 | CE21: 17:38 | CF21: 00:42 | CG21: 0.54 | CI21: 09:11 | CJ21: 17:38 | CK21: 00:35 | CL21: 0.37 | CN21: 08:58 | CO21: 17:12 | CP21: 00:41 | CQ21: 0.06 | CS21: 10:21 | CT21: 18:59 | CU21: 00:36 | CV21: 0.53 | CX21: 18:06 | CY21: 17:39 | CZ21: 00:30 | DA21: 15.54 | DC21: 09:00 | DD21: 17:00 | DE21: 00:30 | DF21: 0 | DH21: 09:00 | DI21: 17:00 | DJ21: 00:30 | DK21: 0 | DM21: 08:57 | DN21: 17:34 | DO21: 00:33 | DP21: 0.56 | DR21: 08:48 | DS21: 18:25 | DT21: 00:41 | DU21: 1.43 | DW21: 09:18 | DX21: 17:52 | DY21: 00:45 | DZ21: 0.33 | EB21: 09:00 | EC21: 17:00 | ED21: 00:30 | EE21: 0 | EG21: 09:00 | EH21: 17:00 | EI21: 00:30 | EJ21: 0 | EL21: 09:16 | EM21: 17:42 | EN21: 00:43 | EO21: 0.21 | EQ21: 09:00 | ER21: 17:00 | ES21: 00:30 | ET21: 0 | EV21: 08:47 | EW21: 17:28 | EX21: 00:46 | EY21: 0.43 | FA21: 09:00 | FB21: 17:00 | FC21: 00:30 | FD21: 0 | FF21: 08:50 | FG21: 17:30 | FH21: 00:43 | FI21: 0.43 | FK21: 09:00 | FL21: 17:00 | FM21: 00:30 | FN21: 0 | FP21: 09:04 | FQ21: 17:43 | FR21: 00:42 | FS21: 0.44 | FU21: 0.37361111 | FV21: 17:39 | FW21: 00:00 | FX21: 1.2 | FZ21: 09:15 | GA21: 17:38 | GB21: 00:31 | GC21: 0.36 | GE21: 09:04 | GF21: 17:40 | GG21: 00:31 | GH21: 0.6 | GJ21: 08:58 | GK21: 18:28 | GL21: 00:32 | GM21: 1.46 | GO21: 08:58 | GP21: 17:39 | GQ21: 00:43 | GR21: 0.46 | GT21: 08:43 | GU21: 17:57 | GV21: 00:36 | GW21: 1.12
A22: 2026-02-18 | B22: 08:45 | C22: 17:02 | D22: 00:37 | E22: 0.18 | G22: 08:53 | H22: 17:53 | I22: 00:44 | J22: 0.77 | L22: 09:00 | M22: 17:00 | N22: 00:30 | O22: 0 | Q22: 08:58 | R22: 17:36 | S22: 00:45 | T22: 0.38 | V22: 09:09 | W22: 17:30 | X22: 00:45 | Y22: 0.1 | AA22: 09:00 | AB22: 17:00 | AC22: 00:30 | AD22: 0 | AF22: 09:47 | AG22: 17:26 | AH22: 00:45 | AI22: -0.6 | AK22: 08:59 | AL22: 17:31 | AM22: 00:30 | AN22: 0.52 | AP22: 09:00 | AQ22: 17:00 | AR22: 00:30 | AS22: 0 | AU22: 09:23 | AV22: 18:40 | AW22: 00:38 | AX22: 1.15 | AZ22: 09:05 | BA22: 17:43 | BB22: 00:45 | BC22: 0.39 | BE22: 09:00 | BF22: 17:00 | BG22: 00:30 | BH22: 0 | BJ22: 09:00 | BK22: 17:00 | BL22: 00:30 | BM22: 0 | BO22: 09:05 | BP22: 17:36 | BQ22: 00:42 | BR22: 0.31 | BT22: 09:00 | BU22: 17:00 | BV22: 00:30 | BW22: 0 | BY22: 09:05 | BZ22: 17:39 | CA22: 00:34 | CB22: 0.51 | CD22: 08:56 | CE22: 17:30 | CF22: 00:43 | CG22: 0.33 | CI22: 09:07 | CJ22: 17:30 | CK22: 00:45 | CL22: 0.12 | CN22: 08:52 | CO22: 20:20 | CP22: 00:40 | CQ22: 3.3 | CS22: 09:00 | CT22: 17:00 | CU22: 00:30 | CV22: 0 | CX22: 09:00 | CY22: 17:00 | CZ22: 00:30 | DA22: 0 | DC22: 09:00 | DD22: 17:00 | DE22: 00:30 | DF22: 0 | DH22: 09:38 | DI22: 17:34 | DJ22: 00:46 | DK22: -0.33 | DM22: 09:00 | DN22: 17:00 | DO22: 00:30 | DP22: 0 | DR22: 08:42 | DS22: 20:30 | DT22: 00:36 | DU22: 3.7 | DW22: 09:13 | DX22: 17:41 | DY22: 00:39 | DZ22: 0.31 | EB22: 09:00 | EC22: 17:00 | ED22: 00:30 | EE22: 0 | EG22: 09:00 | EH22: 17:00 | EI22: 00:30 | EJ22: 0 | EL22: 09:20 | EM22: 17:35 | EN22: 00:40 | EO22: 0.08 | EQ22: 08:34 | ER22: 18:24 | ES22: 00:32 | ET22: 1.81 | EV22: 09:00 | EW22: 17:00 | EX22: 00:30 | EY22: 0 | FA22: 09:00 | FB22: 17:00 | FC22: 00:30 | FD22: 0 | FF22: 08:45 | FG22: 18:08 | FH22: 00:30 | FI22: 1.37 | FK22: 08:50 | FL22: 17:38 | FM22: 00:31 | FN22: 0.79 | FP22: 08:46 | FQ22: 17:38 | FR22: 00:40 | FS22: 0.71 | FU22: 09:05 | FV22: 17:40 | FW22: 00:42 | FX22: 0.39 | FZ22: 09:11 | GA22: 17:39 | GB22: 00:37 | GC22: 0.34 | GE22: 13:48 | GF22: 17:39 | GG22: 00:34 | GH22: -4.22 | GJ22: 08:57 | GK22: 17:46 | GL22: 00:42 | GM22: 0.62 | GO22: 08:32 | GP22: 17:51 | GQ22: 00:42 | GR22: 1.11 | GT22: 08:29 | GU22: 17:30 | GV22: 00:37 | GW22: 0.88
A23: Total Variation | E23: 2.29 | J23: 6.9 | O23: -3.54 | T23: 17.11 | Y23: 4.98 | AD23: 3.32 | AI23: -1.48 | AN23: 3.84 | AS23: 16.69 | AX23: 12.9 | BC23: 7.72 | BH23: 9.78 | BM23: 5.37 | BR23: 3.36 | BW23: -6.19 | CB23: 2.57 | CG23: 7.18 | CL23: 15.39 | CQ23: 38.14 | CV23: 6.71 | DA23: 11.54 | DF23: -0.57 | DK23: -4.69 | DP23: 6.22 | DU23: 5.69 | DZ23: 2.32 | EE23: -4.84 | EJ23: -2.62 | EO23: 2.88 | ET23: 12.73 | EY23: 4.54 | FD23: 2.03 | FI23: 3.49 | FN23: 6.71 | FS23: 7.37 | FX23: =SUM(FX6:FX22) -> 5.54 | GC23: -0.09 | GH23: -1.88 | GM23: 7.6 | GR23: 4.04 | GW23: 16.59

Sheet Time by Department
A1: Time by Department
A2: (27th Jan 2026 - 18th Feb 2026)
A4: Department | B4: Headcount | C4: Column1 | D4: Total Variance
A5: Agri | B5: 5 | C5: 68.22 | D5: =TEXT(C5/24,"[h]:mm") -> 68:13
A6: Engineering | B6: 3 | C6: 21.66 | D6: =TEXT(C6/24,"[h]:mm") -> 21:39
A7: Finance | B7: 6 | C7: 35.71 | D7: =TEXT(C7/24,"[h]:mm") -> 35:42
A8: Group Finance | B8: 3 | C8: 1.31 | D8: =TEXT(C8/24,"[h]:mm") -> 1:18
A9: Group Legal | B9: 3 | C9: 22.24 | D9: =TEXT(C9/24,"[h]:mm") -> 22:14
A10: HR | B10: 1 | C10: -2.67 | D10: 0.22916667
A11: Investment | B11: 4 | C11: 25.68 | D11: =TEXT(C11/24,"[h]:mm") -> 25:40
A12: Operations | B12: 4 | C12: 33.67 | D12: =TEXT(C12/24,"[h]:mm") -> 33:40
A13: Property | B13: 2 | C13: -7.31 | D13: =TEXT(C13/24,"[h]:mm") -> -7:18
A14: UG Business Support | B14: 2 | C14: -4.11 | D14: =TEXT(C14/24,"[h]:mm") -> -4:06
A15: UK BDM | B15: 8 | C15: 35.03 | D15: =TEXT(C15/24,"[h]:mm") -> 35:01

Sheet Time by Country
A1: Time by Country
A2: (27th Jan 2026 - 18th Feb 2026)
A4: Country | B4: Headcount | C4: Column1 | D4: Total Variance
A5: UK | B5: 41 | C5: 229.43 | D5: =TEXT(C5/24,"[h]:mm") -> 229:25

Sheet Time by Group 
A1: Time by Group
A2: (27th Jan 2026 - 18th Feb 2026)
A4: Group | B4: Headcount | C4: Column1 | D4: Total Variance
A5: AG | B5: 5 | C5: 68.22 | D5: =TEXT(C5/24,"[h]:mm") -> 68:13
A6: EG | B6: 20 | C6: 113.37 | D6: =TEXT(C6/24,"[h]:mm") -> 113:22
A7: UG | B7: 16 | C7: 47.84 | D7: =TEXT(C7/24,"[h]:mm") -> 47:50

Sheet Sheet1
A1: Alex McGregor | B1: 2.29
A2: Amine El Fassi | B2: 6.9
A3: Andreea Cartianu | B3: -3.54
A4: Ariana Mashad | B4: 17.11
A5: Barış Akyüz | B5: 4.98
A6: Charles Jones | B6: 3.32
A7: Daniel Imran | B7: -1.48
A8: Dominic Richardson | B8: 3.84
A9: Dominick Mahon | B9: 16.69
A10: Ecaterina Turcanu | B10: 12.9
A11: Elena Sarieva | B11: 7.72
A12: Eugene Sun | B12: 9.78
... A41: Yi Jiang | B41: 16.59
